bot running
Traceback (most recent call last):
  File "main.py", line 310, in <module>
    input('')
OSError: [Errno 9] Bad file descriptor
bot running
Traceback (most recent call last):
  File "main.py", line 310, in <module>
    input('')
OSError: [Errno 9] Bad file descriptor
bot running
Traceback (most recent call last):
  File "main.py", line 310, in <module>
    input('')
OSError: [Errno 9] Bad file descriptor
